<?xml version="1.0" ?>
<!-- =================================================================================== -->
<!-- |    This document was autogenerated by xacro from rmp.urdf.xacro                 | -->
<!-- |    EDITING THIS FILE BY HAND IS NOT RECOMMENDED                                 | -->
<!-- =================================================================================== -->
<!--
Software License Agreement (BSD)

\file      segway.urdf.xacro
\authors   Patrick Hussey
\copyright Copyright (c) 2018, Stanley Innovation, Inc., All rights reserved.

Redistribution and use in source and binary forms, with or without modification, are permitted provided that
the following conditions are met:
 * Redistributions of source code must retain the above copyright notice, this list of conditions and the
   following disclaimer.
 * Redistributions in binary form must reproduce the above copyright notice, this list of conditions and the
   following disclaimer in the documentation and/or other materials provided with the distribution.
 * Neither the name of Stanley Innovation, Inc. nor the names of its contributors may be used to endorse or promote
   products derived from this software without specific prior written permission.

THIS SOFTWARE IS PROVIDED BY THE COPYRIGHT HOLDERS AND CONTRIBUTORS "AS IS" AND ANY EXPRESS OR IMPLIED WAR-
RANTIES, INCLUDING, BUT NOT LIMITED TO, THE IMPLIED WARRANTIES OF MERCHANTABILITY AND FITNESS FOR A PARTICULAR
PURPOSE ARE DISCLAIMED. IN NO EVENT SHALL THE COPYRIGHT HOLDER OR CONTRIBUTORS BE LIABLE FOR ANY DIRECT, IN-
DIRECT, INCIDENTAL, SPECIAL, EXEMPLARY, OR CONSEQUENTIAL DAMAGES (INCLUDING, BUT NOT LIMITED TO, PROCUREMENT
OF SUBSTITUTE GOODS OR SERVICES; LOSS OF USE, DATA, OR PROFITS; OR BUSINESS INTERRUPTION) HOWEVER CAUSED AND
ON ANY THEORY OF LIABILITY, WHETHER IN CONTRACT, STRICT LIABILITY, OR TORT (INCLUDING NEGLIGENCE OR OTHERWISE)
ARISING IN ANY WAY OUT OF THE USE OF THIS SOFTWARE, EVEN IF ADVISED OF THE POSSIBILITY OF SUCH DAMAGE.
-->
<robot name="segway_robot" xmlns:xacro="http://ros.org/wiki/xacro">
  <gazebo>
    <plugin filename="libgazebo_ros_control.so" name="gazebo_ros_control">
      <robotNamespace>/</robotNamespace>
    </plugin>
    <plugin filename="libgazebo_ros_p3d.so" name="gazebo_ros_p3d">
      <bodyName>base_link</bodyName>
      <topicName>ground_truth_odom</topicName>
      <alwaysOn>true</alwaysOn>
      <updateRate>100.0</updateRate>
    </plugin>
  </gazebo>
  <!-- Base link is the center of the robot's chassis between the motors projected on the ground -->
  <link name="base_link">
  <inertial>
      <mass value="0.001"/>
      <origin rpy="0 0 0" xyz="0 0 0"/>
      <inertia ixx="0.0001" ixy="0.0" ixz="0.0" iyy="0.0001" iyz="0.0" izz="0.0001"/>
    </inertial>
  </link>
  <joint name="base_chassis_joint" type="fixed">
    <origin rpy="0 0 0" xyz="0 0 0.15801795"/>
    <parent link="base_link"/>
    <child link="base_chassis_link"/>
  </joint>
  <link name="base_chassis_link">
    <inertial>
      <mass value="101.0333036"/>
      <origin xyz="0 0 0.202000"/>
      <inertia ixx="5.38268396036" ixy="0" ixz="0" iyy="5.38268396036" iyz="0" izz="5.38268396036"/>
    </inertial>
    <collision>
      <geometry>
        <mesh filename="meshes/segway_components/collision/fixed_chassis_collision.stl"/>
      </geometry>
    </collision>
    <visual>
      <origin rpy="0 0 0" xyz="0 0 0"/>
      <geometry>
        <mesh filename="meshes/segway_components/visual/processed_fixed_chassis.obj"/>
      </geometry>
          <material name="">
        <color rgba="1 1 1 1" />
      </material>
</visual>
  </link>

<joint name="jr2_fixed_body_joint" type="fixed">
    <parent link="base_chassis_link"/>
    <child link="jr2_fixed_body_link"/>
    <origin rpy="0 0 0" xyz="0 0 0"/>
  </joint>
  <link name="jr2_fixed_body_link">
    <visual>
      <origin rpy="0 0 0" xyz="0 0 0"/>
      <geometry>
        <mesh filename="meshes/segway_components/visual/processed_fixed_body_highres.obj" scale="1.0 1.0 1.0"/>
      </geometry>
    </visual>
    <collision>
      <origin rpy="0 0 0" xyz="0 0 0"/>
      <geometry>
        <mesh filename="meshes/segway_components/visual/fixed_body_vhacd.obj" scale="1.0 1.0 1.0"/>
      </geometry>
    </collision>
    <inertial>
      <mass value="0.001"/>
      <origin rpy="0 0 0" xyz="0 0 0"/>
      <inertia ixx="0.0001" ixy="0.0" ixz="0.0" iyy="0.0001" iyz="0.0" izz="0.0001"/>
    </inertial>
  </link>

  <joint name="left_wheel" type="continuous">
    <parent link="base_chassis_link"/>
    <child link="left_wheel_link"/>
    <origin rpy="0 0 0" xyz="0 0.27105 0.08255015"/>
    <axis rpy="0 0 0" xyz="0 1 0"/>
  </joint>
  <gazebo reference="left_wheel">
    <implicitSpringDamper>1</implicitSpringDamper>
    <stopCfm>0.1</stopCfm>
    <stopErp>0.2</stopErp>
  </gazebo>
  <link name="left_wheel_link">
    <inertial>
      <mass value="20.0"/>
      <origin rpy="0 0 0" xyz="0 0 0"/>
      <inertia ixx="0.303625" ixy="0.000000" ixz="0.000000" iyx="0.000000" iyy="0.303625" iyz="0.000000" izx="0.000000" izy="0.000000" izz="0.578884"/>
    </inertial>
    <visual>
      <origin rpy="-1.570795 0 0" xyz="0 0 0"/>
      <geometry>
        <mesh filename="meshes/segway_components/visual/processed_i2_wheel.obj"/>
      </geometry>
          <material name="">
        <color rgba="1 1 1 1" />
      </material>
</visual>
    <collision>
      <origin rpy="-1.570795 0 0" xyz="0 0 0"/>
      <geometry>
        <cylinder length="0.092249" radius="0.2406"/>
      </geometry>
    </collision>

    <contact>
      <lateral_friction value="1.0"/>
      <rolling_friction value="0.0"/>
    <stiffness value="300000"/>
<damping value="30000"/>
    </contact>


  </link>
  <gazebo reference="left_wheel_link">
    <mu1>10</mu1>
    <mu2>10</mu2>
    <kp>5000000.0</kp>
    <kd>10.0</kd>
    <minDepth>0.001</minDepth>
    <maxVel>0.1</maxVel>
    <fdir1>1 0 0</fdir1>
  </gazebo>
  <transmission name="left_wheel_trans" type="SimpleTransmission">
    <type>transmission_interface/SimpleTransmission</type>
    <actuator name="left_wheel_motor">
      <mechanicalReduction>1</mechanicalReduction>
    </actuator>
    <joint name="left_wheel">
      <hardwareInterface>hardware_interface/VelocityJointInterface</hardwareInterface>
    </joint>
  </transmission>
  <joint name="right_wheel" type="continuous">
    <parent link="base_chassis_link"/>
    <child link="right_wheel_link"/>
    <origin rpy="0 0 0" xyz="0 -0.27105 0.08255015"/>
    <axis rpy="0 0 0" xyz="0 1 0"/>
  </joint>
  <gazebo reference="right_wheel">
    <implicitSpringDamper>1</implicitSpringDamper>
    <stopCfm>0.1</stopCfm>
    <stopErp>0.2</stopErp>
  </gazebo>
  <link name="right_wheel_link">
    <inertial>
      <mass value="20.0"/>
      <origin rpy="0 0 0" xyz="0 0 0"/>
      <inertia ixx="0.303625" ixy="0.000000" ixz="0.000000" iyx="0.000000" iyy="0.303625" iyz="0.000000" izx="0.000000" izy="0.000000" izz="0.578884"/>
    </inertial>
    <visual>
      <origin rpy="1.570795 0 0" xyz="0 0 0"/>
      <geometry>
        <mesh filename="meshes/segway_components/visual/processed_i2_wheel.obj"/>
      </geometry>
          <material name="">
        <color rgba="1 1 1 1" />
      </material>
</visual>
    <collision>
      <origin rpy="1.570795 0 0" xyz="0 0 0"/>
      <geometry>
        <cylinder length="0.092249" radius="0.2406"/>
      </geometry>
    </collision>

    <contact>
      <lateral_friction value="1.0"/>
      <rolling_friction value="0.0"/>
    <stiffness value="300000"/>
<damping value="30000"/>
    </contact>

  </link>
  <gazebo reference="right_wheel_link">
    <mu1>10</mu1>
    <mu2>10</mu2>
    <kp>5000000.0</kp>
    <kd>10.0</kd>
    <minDepth>0.001</minDepth>
    <maxVel>0.1</maxVel>
    <fdir1>1 0 0</fdir1>
  </gazebo>
  <transmission name="right_wheel_trans" type="SimpleTransmission">
    <type>transmission_interface/SimpleTransmission</type>
    <actuator name="right_wheel_motor">
      <mechanicalReduction>1</mechanicalReduction>
    </actuator>
    <joint name="right_wheel">
      <hardwareInterface>hardware_interface/VelocityJointInterface</hardwareInterface>
    </joint>
  </transmission>
  <link name="front_caster_pivot_link">
    <inertial>
      <mass value="0.0001"/>
      <origin rpy="0 0 0" xyz="0 0 0"/>
      <inertia ixx="0.0000001" ixy="0.0" ixz="0.0" iyy="0.0000001" iyz="0.0" izz="0.0000001"/>
    </inertial>
    <collision>
      <geometry>
        <mesh filename="meshes/segway_components/collision/frogleg_caster_pivot_collision.stl"/>
      </geometry>
    </collision>
  </link>
  <joint name="front_caster_pivot_joint" type="fixed">
    <origin rpy="0 0 3.14159" xyz="0.385841 0 0.051100"/>
    <parent link="base_chassis_link"/>
    <child link="front_caster_pivot_link"/>
  </joint>
  <link name="front_caster_wheel_link">
    <inertial>
      <mass value="1"/>
      <origin rpy="0 0 0" xyz="-0.1 0 0"/>
      <inertia ixx="0.002794" ixy="0.0" ixz="0.0" iyy="0.002794" iyz="0.0" izz="0.002794"/>
    </inertial>
    <collision>
      <geometry>
        <sphere radius="0.083571637"/>
      </geometry>
    </collision>

    <contact>
      <lateral_friction value="0.0"/>
      <rolling_friction value="0.0"/>
      <stiffness value="500000"/>
      <damping value="30000"/>
    </contact>

  </link>
  <joint name="front_caster_wheel_joint" type="fixed">
    <origin rpy="-1.570795 0 0" xyz="-0.055330 0 -0.125551"/>
    <parent link="front_caster_pivot_link"/>
    <child link="front_caster_wheel_link"/>
  </joint>
  <gazebo reference="front_caster_wheel_link">
    <mu1>0.0</mu1>
    <mu2>0.0</mu2>
    <kp>10000000.0</kp>
    <kd>100.0</kd>
    <minDepth>0.01</minDepth>
    <maxVel>10.0</maxVel>
  </gazebo>
  <link name="rear_caster_pivot_link">
    <inertial>
      <mass value="0.0001"/>
      <origin rpy="0 0 0" xyz="0 0 0"/>
      <inertia ixx="0.0000001" ixy="0.0" ixz="0.0" iyy="0.0000001" iyz="0.0" izz="0.0000001"/>
    </inertial>
    <collision>
      <geometry>
        <mesh filename="meshes/segway_components/collision/frogleg_caster_pivot_collision.stl"/>
      </geometry>
    </collision>
  </link>
  <joint name="rear_caster_pivot_joint" type="fixed">
    <origin rpy="0 0 0" xyz="-0.314721 0 0.051100"/>
    <parent link="base_chassis_link"/>
    <child link="rear_caster_pivot_link"/>
  </joint>
  <link name="rear_caster_wheel_link">
    <inertial>
      <mass value="1"/>
      <origin rpy="0 0 0" xyz="0 0 0"/>
      <inertia ixx="0.002794" ixy="0.0" ixz="0.0" iyy="0.002794" iyz="0.0" izz="0.002794"/>
    </inertial>
    <collision>
      <geometry>
        <sphere radius="0.083571637"/>
      </geometry>
    </collision>

    <contact>
      <lateral_friction value="0.0"/>
      <rolling_friction value="0.0"/>
 <stiffness value="300000"/>
<damping value="30000"/> 
    </contact>

  </link>
  <joint name="rear_caster_wheel_joint" type="fixed">
    <origin rpy="-1.570795 0 0" xyz="-0.055330 0 -0.125551"/>
    <parent link="rear_caster_pivot_link"/>
    <child link="rear_caster_wheel_link"/>
  </joint>
  <gazebo reference="rear_caster_wheel_link">
    <mu1>0.0</mu1>
    <mu2>0.0</mu2>
    <kp>10000000.0</kp>
    <kd>100.0</kd>
    <minDepth>0.01</minDepth>
    <maxVel>10.0</maxVel>
  </gazebo>
  <!-- CH Robotics UM7 Link-->
  <link name="ext_imu_frame">
  <inertial>
      <mass value="0.001"/>
      <origin rpy="0 0 0" xyz="0 0 0"/>
      <inertia ixx="0.0001" ixy="0.0" ixz="0.0" iyy="0.0001" iyz="0.0" izz="0.0001"/>
    </inertial>
    </link>
  <joint name="ext_imu_joint" type="fixed">
    <origin rpy="3.14159 0 1.570795" xyz="0.053540 0 0.086597"/>
    <parent link="base_chassis_link"/>
    <child link="ext_imu_frame"/>
  </joint>
  <gazebo>
    <plugin filename="libhector_gazebo_ros_imu.so" name="imu_controller">
      <alwaysOn>1</alwaysOn>
      <updateRate>50.0</updateRate>
      <bodyName>ext_imu_frame</bodyName>
      <topicName>/segway/feedback/ext_imu</topicName>
      <accelDrift>0.005 0.005 0.005</accelDrift>
      <accelGaussianNoise>0.005 0.005 0.005</accelGaussianNoise>
      <rateDrift>0.005 0.005 0.005 </rateDrift>
      <rateGaussianNoise>0.005 0.005 0.005 </rateGaussianNoise>
      <headingDrift>0.005</headingDrift>
      <headingGaussianNoise>0.005</headingGaussianNoise>
    </plugin>
  </gazebo>
  <link name="rear_laser_link">
  <inertial>
      <mass value="0.001"/>
      <origin rpy="0 0 0" xyz="0 0 0"/>
      <inertia ixx="0.0001" ixy="0.0" ixz="0.0" iyy="0.0001" iyz="0.0" izz="0.0001"/>
    </inertial>
  </link>
  <joint name="rear_laser_joint" type="fixed">
    <origin rpy="0 0 3.14159" xyz="-0.336957 0 0.137117"/>
    <parent link="base_chassis_link"/>
    <child link="rear_laser_link"/>
  </joint>
  <gazebo reference="rear_laser_link">
    <sensor name="rear_tim_laser" type="gpu_ray">
      <pose>0 0 0 0 0 0</pose>
      <visualize>false</visualize>
      <update_rate>15</update_rate>
      <ray>
        <scan>
          <horizontal>
            <samples>660</samples>
            <resolution>1</resolution>
            <min_angle>-1.9</min_angle>
            <max_angle>1.9</max_angle>
          </horizontal>
        </scan>
        <range>
          <min>0.10</min>
          <max>20.0</max>
          <resolution>0.01</resolution>
        </range>
        <noise>
          <type>gaussian</type>
          <mean>0.0</mean>
          <stddev>0.0</stddev>
        </noise>
      </ray>
      <plugin filename="libgazebo_ros_gpu_laser.so" name="rear_tim_node">
        <topicName>/segway/rear_scan</topicName>
        <frameName>rear_laser_link</frameName>
      </plugin>
    </sensor>
  </gazebo>
  <link name="front_laser_link">
  <inertial>
      <mass value="0.001"/>
      <origin rpy="0 0 0" xyz="0 0 0"/>
      <inertia ixx="0.0001" ixy="0.0" ixz="0.0" iyy="0.0001" iyz="0.0" izz="0.0001"/>
    </inertial>
  </link>
  <joint name="front_laser_joint" type="fixed">
    <origin rpy="0 0 0" xyz="0.336957 0 0.137117"/>
    <parent link="base_chassis_link"/>
    <child link="front_laser_link"/>
  </joint>
  <gazebo reference="front_laser_link">
    <sensor name="front_tim_laser" type="gpu_ray">
      <pose>0 0 0 0 0 0</pose>
      <visualize>false</visualize>
      <update_rate>15</update_rate>
      <ray>
        <scan>
          <horizontal>
            <samples>660</samples>
            <resolution>1</resolution>
            <min_angle>-1.9</min_angle>
            <max_angle>1.9</max_angle>
          </horizontal>
        </scan>
        <range>
          <min>0.10</min>
          <max>20.0</max>
          <resolution>0.01</resolution>
        </range>
        <noise>
          <type>gaussian</type>
          <mean>0.0</mean>
          <stddev>0.0</stddev>
        </noise>
      </ray>
      <plugin filename="libgazebo_ros_gpu_laser.so" name="front_tim_node">
        <topicName>/segway/front_scan</topicName>
        <frameName>front_laser_link</frameName>
      </plugin>
    </sensor>
  </gazebo>
  <link name="lower_velodyne_frame">
  <inertial>
      <mass value="0.001"/>
      <origin rpy="0 0 0" xyz="0 0 0"/>
      <inertia ixx="0.0001" ixy="0.0" ixz="0.0" iyy="0.0001" iyz="0.0" izz="0.0001"/>
    </inertial>
  </link>
  <joint name="lower_velodyne_joint" type="fixed">
    <origin rpy="0 0 0" xyz="-0.019685 0 0.606982"/>
    <parent link="base_chassis_link"/>
    <child link="lower_velodyne_frame"/>
  </joint>
  <!--gazebo reference="lower_velodyne_frame">>
            <sensor type="ray" name="lower_velodyne">
                <pose>0 0 0 0 0 0</pose>
                <visualize>false</visualize>
                <update_rate>10</update_rate>
                <ray>
                    <scan>
                        <horizontal>
                            <samples>1090</samples>
                            <resolution>1</resolution>
                            <min_angle>${-M_PI}</min_angle>
                            <max_angle>${M_PI}</max_angle>
                        </horizontal>
                        <vertical>
                            <samples>16</samples>
                            <resolution>1</resolution>
                            <min_angle>-${15.0*M_PI/180.0}</min_angle>
                            <max_angle> ${15.0*M_PI/180.0}</max_angle>
                        </vertical>
                    </scan>
                    <range>
                        <min>0.9</min>
                        <max>20.0</max>
                        <resolution>0.001</resolution>
                    </range>
                    <noise>
                        <type>gaussian</type>
                        <mean>0.0</mean>
                        <stddev>0.0</stddev>
                    </noise>
                </ray>
                <plugin name="lower_velodyne_plugin" filename="libgazebo_ros_block_laser.so">
                    <updateRate>10.0</updateRate>
                    <topicName>/lower_velodyne_pointcloud</topicName>
                    <frameName>lower_velodyne_frame</frameName>
                </plugin>

            </sensor>
        </gazebo-->
  <link name="occam">
  <inertial>
      <mass value="0.001"/>
      <origin rpy="0 0 0" xyz="0 0 0"/>
      <inertia ixx="0.0001" ixy="0.0" ixz="0.0" iyy="0.0001" iyz="0.0" izz="0.0001"/>
    </inertial>
    </link>
  <joint name="ocamm_omni_joint" type="fixed">
    <origin rpy="-1.570795 0 -1.570795" xyz="-0.019685 0 0.742092"/>
    <parent link="base_chassis_link"/>
    <child link="occam"/>
  </joint>
  <link name="occam_omni_optical_link">
  <inertial>
      <mass value="0.001"/>
      <origin rpy="0 0 0" xyz="0 0 0"/>
      <inertia ixx="0.0001" ixy="0.0" ixz="0.0" iyy="0.0001" iyz="0.0" izz="0.0001"/>
    </inertial>
  </link>
  <joint name="ocamm_omni_optical_joint" type="fixed">
    <origin rpy="0 1.570795 -1.570795" xyz="0 0 0"/>
    <parent link="occam"/>
    <child link="occam_omni_optical_link"/>
  </joint>
  <link name="upper_velodyne_frame">
  <inertial>
      <mass value="0.001"/>
      <origin rpy="0 0 0" xyz="0 0 0"/>
      <inertia ixx="0.0001" ixy="0.0" ixz="0.0" iyy="0.0001" iyz="0.0" izz="0.0001"/>
    </inertial>
  </link>
  <joint name="upper_velodyne_joint" type="fixed">
    <origin rpy="0 0 0.085" xyz="-0.019685 0 1.077382"/>
    <parent link="base_chassis_link"/>
    <child link="upper_velodyne_frame"/>
  </joint>
  <!--gazebo reference="upper_velodyne_frame">
            <sensor name="upper_velodyne" type="ray">
                <pose>0 0 0 0 0 0</pose>
                <visualize>false</visualize>
                <update_rate>10</update_rate>
                <ray>
                    <scan>
                        <horizontal>
                            <samples>1090</samples>
                            <resolution>1</resolution>
                            <min_angle>${-M_PI}</min_angle>
                            <max_angle>${M_PI}</max_angle>
                        </horizontal>
                        <vertical>
                            <samples>16</samples>
                            <resolution>1</resolution>
                            <min_angle>-${15.0*M_PI/180.0}</min_angle>
                            <max_angle> ${15.0*M_PI/180.0}</max_angle>
                        </vertical>
                    </scan>
                    <range>
                        <min>0.9</min>
                        <max>20.0</max>
                        <resolution>0.001</resolution>
                    </range>
                    <noise>
                        <type>gaussian</type>
                        <mean>0.0</mean>
                        <stddev>0.0</stddev>
                    </noise>
                </ray>
                <plugin name="upper_velodyne_plugin" filename="libgazebo_ros_block_laser.so">
                    <updateRate>10.0</updateRate>
                    <topicName>/upper_velodyne_pointcloud</topicName>
                    <frameName>upper_velodyne_frame</frameName>
                </plugin>

            </sensor>
        </gazebo-->
  <link name="gps_frame">
  <inertial>
      <mass value="0.001"/>
      <origin rpy="0 0 0" xyz="0 0 0"/>
      <inertia ixx="0.0001" ixy="0.0" ixz="0.0" iyy="0.0001" iyz="0.0" izz="0.0001"/>
    </inertial>
  </link>
  <joint name="gps_joint" type="fixed">
    <origin rpy="0 0 -1.570795" xyz="-0.019685 0 1.116244"/>
    <parent link="base_chassis_link"/>
    <child link="gps_frame"/>
  </joint>
  <gazebo>
    <plugin filename="libhector_gazebo_ros_gps.so" name="gps_controller">
      <alwaysOn>1</alwaysOn>
      <updateRate>40</updateRate>
      <bodyName>gps_frame</bodyName>
      <topicName>/segway/feedback/gps/fix_2d</topicName>
      <velocityTopicName>/segway/feedback/gps/vel</velocityTopicName>
      <referenceLatitude>40.712784</referenceLatitude>
      <referenceLongitude>-74.005941</referenceLongitude>
      <referenceHeading>0</referenceHeading>
      <referenceAltitude>0</referenceAltitude>
      <drift>0.0001 0.0001 0.0001</drift>
    </plugin>
  </gazebo>
  <joint name="pan_joint" type="revolute">
    <origin rpy="0 0 0" xyz="0.043815 0 0.886186"/>
    <axis xyz="0 0 1"/>
    <parent link="base_chassis_link"/>
    <child link="pan_link"/>
    <limit effort="60.0" lower="-1.570796326794897" upper="1.570796326794897" velocity="6.597"/>
  </joint>
  <link name="pan_link">
    <inertial>
      <mass value="0.142314"/>
      <origin xyz="-0.000098 -0.000421 0.038035"/>
      <inertia ixx="0.000065" ixy="0.000001" ixz="0.000000" iyx="0.000001" iyy="0.000055" iyz="-0.000002" izx="0.00000" izy="-0.000002" izz="0.000034"/>
    </inertial>
    <visual>
      <origin rpy="0 0 0" xyz="0 0 0"/>
      <geometry>
        <mesh filename="meshes/segway_components/visual/processed_tilt_servo.obj"/>
      </geometry>
          <material name="">
        <color rgba="1 1 1 1" />
      </material>
</visual>
    <collision>
      <origin rpy="0 0 0" xyz="0 0 0"/>
      <geometry>
        <mesh filename="meshes/segway_components/collision/tilt_servo_collision.stl"/>
      </geometry>
    </collision>
  </link>
  <transmission name="pan_trans" type="SimpleTransmission">
    <type>transmission_interface/SimpleTransmission</type>
    <joint name="pan_joint">
      <hardwareInterface>hardware_interface/EffortJointInterface</hardwareInterface>
    </joint>
    <actuator name="pan_actuator">
      <mechanicalReduction>1</mechanicalReduction>
    </actuator>
  </transmission>
  <link name="tilt_link">
    <inertial>
      <mass value="0.531983"/>
      <origin xyz="0.077660 -0.013492 0.006611"/>
      <inertia ixx="0.001766" ixy="0.000001" ixz="-0.000024" iyx="0.000001" iyy="0.001253" iyz="0.000022" izx="-0.000024" izy="0.000022" izz="0.000629"/>
    </inertial>
    <visual>
      <origin rpy="0 0 0" xyz="0 0 0"/>
      <geometry>
        <mesh filename="meshes/segway_components/visual/processed_touch_screen.obj"/>
      </geometry>
          <material name="">
        <color rgba="1 1 1 1" />
      </material>
</visual>
    <collision>
      <origin rpy="0 0 0" xyz="0 0 0"/>
      <geometry>
        <mesh filename="meshes/segway_components/collision/touch_screen_collision.stl"/>
      </geometry>
    </collision>
  </link>
  <joint name="tilt_joint" type="revolute">
    <origin rpy="-1.570795 0 0" xyz="0 0 0.055000"/>
    <axis xyz="0 0 1"/>
    <parent link="pan_link"/>
    <child link="tilt_link"/>
    <limit effort="60.0" lower="-1.570796326794897" upper="1.570796326794897" velocity="6.597"/>
  </joint>
  <transmission name="tilt_trans" type="SimpleTransmission">
    <type>transmission_interface/SimpleTransmission</type>
    <joint name="tilt_joint">
      <hardwareInterface>hardware_interface/EffortJointInterface</hardwareInterface>
    </joint>
    <actuator name="tilt_actuator">
      <mechanicalReduction>1</mechanicalReduction>
    </actuator>
  </transmission>
  <joint name="camera_joint" type="fixed">
    <origin rpy="1.57 0 0" xyz="0.08 0.075 0.0"/>
    <parent link="tilt_link"/>
    <child link="camera_link"/>
  </joint>
  <link name="camera_link">
    <inertial>
      <mass value="0.1"/>
      <origin xyz="0 0 0"/>
      <inertia ixx="0.001767" ixy="0.0" ixz="0.0" iyx="0.0" iyy="0.001789" iyz="0.0" izx="0.0" izy="0.0" izz="0.002159"/>
    </inertial>
    <visual>
      <geometry>
        <mesh filename="meshes/additional_sensors/visual/ZED.stl"/>
      </geometry>
          <material name="">
        <color rgba="1 1 1 1" />
      </material>
</visual>
    <collision>
      <geometry>
        <box size="0.033 0.175 0.030"/>
      </geometry>
    </collision>
  </link>


  <!-- ZED left camera frame -->
  <link name="camera_rgb_frame">
  <inertial>
      <mass value="0.001"/>
      <origin rpy="0 0 0" xyz="0 0 0"/>
      <inertia ixx="0.0001" ixy="0.0" ixz="0.0" iyy="0.0001" iyz="0.0" izz="0.0001"/>
    </inertial>
  </link>
  <joint name="camera_rgb_joint" type="fixed">
    <origin rpy="0 0 0" xyz="0 0.06 0"/>
    <parent link="camera_link"/>
    <child link="camera_rgb_frame"/>
  </joint>
  <link name="camera_rgb_optical_frame">
  <inertial>
      <mass value="0.001"/>
      <origin rpy="0 0 0" xyz="0 0 0"/>
      <inertia ixx="0.0001" ixy="0.0" ixz="0.0" iyy="0.0001" iyz="0.0" izz="0.0001"/>
    </inertial>
  </link>
  <joint name="camera_rgb_optical_joint" type="fixed">
    <origin rpy="-1.57075 0 -1.57075" xyz="0 0 0"/>
    <parent link="camera_rgb_frame"/>
    <child link="camera_rgb_optical_frame"/>
  </joint>
  <!-- Same as ZED left camera frame -->
  <link name="camera_depth_frame">
  <inertial>
      <mass value="0.001"/>
      <origin rpy="0 0 0" xyz="0 0 0"/>
      <inertia ixx="0.0001" ixy="0.0" ixz="0.0" iyy="0.0001" iyz="0.0" izz="0.0001"/>
    </inertial>
    </link>
  <joint name="camera_depth_joint" type="fixed">
    <origin rpy="0 0 0" xyz="0 0.06 0"/>
    <parent link="camera_link"/>
    <child link="camera_depth_frame"/>
  </joint>
  <link name="camera_depth_optical_frame">
  <inertial>
      <mass value="0.001"/>
      <origin rpy="0 0 0" xyz="0 0 0"/>
      <inertia ixx="0.0001" ixy="0.0" ixz="0.0" iyy="0.0001" iyz="0.0" izz="0.0001"/>
    </inertial>
    </link>
  <joint name="camera_depth_optical_joint" type="fixed">
    <origin rpy="-1.57075 0 -1.57075" xyz="0 0 0"/>
    <parent link="camera_depth_frame"/>
    <child link="camera_depth_optical_frame"/>
  </joint>
  <gazebo reference="camera_link">
    <material>Gazebo/Grey</material>
    <sensor name="camera" type="depth">
      <always_on>true</always_on>
      <update_rate>30</update_rate>
      <camera>
        <horizontal_fov>1.57</horizontal_fov>
        <image>
          <format>R8G8B8</format>
          <width>672</width>
          <height>376</height>
        </image>
        <clip>
          <near>0.05</near>
          <far>10.0</far>
        </clip>
      </camera>
      <plugin filename="libgazebo_ros_openni_kinect.so" name="kinect_camera_controller">
        <cameraName>camera</cameraName>
        <alwaysOn>true</alwaysOn>
        <updateRate>20</updateRate>
        <imageTopicName>rgb/image_rect_color</imageTopicName>
        <depthImageTopicName>depth_registered/image_raw</depthImageTopicName>
        <pointCloudTopicName>depth_registered/points</pointCloudTopicName>
        <cameraInfoTopicName>rgb/camera_info</cameraInfoTopicName>
        <depthImageCameraInfoTopicName>depth_registered/camera_info</depthImageCameraInfoTopicName>
        <pointCloudCutoff>0.4</pointCloudCutoff>
        <pointCloudCutoffMax>10.0</pointCloudCutoffMax>
        <frameName>camera_rgb_optical_frame</frameName>
        <baseline>0.1</baseline>
        <distortion_k1>0.0</distortion_k1>
        <distortion_k2>0.0</distortion_k2>
        <distortion_k3>0.0</distortion_k3>
        <distortion_t1>0.0</distortion_t1>
        <distortion_t2>0.0</distortion_t2>
        <CxPrime>0</CxPrime>
        <Cx>0</Cx>
        <Cy>0</Cy>
        <focalLength>0</focalLength>
        <hackBaseline>0</hackBaseline>
      </plugin>
    </sensor>
  </gazebo>
  <!-- Head mounted Intel Realsense D435 RGB-D camera-->
  <!--
        <xacro:intel_realsense_d435 parent="tilt_link" rgbd_prefix="camera">
           <origin xyz="0.05 0 0.05" rpy="0 0 0"/>
           </xacro:intel_realsense_d435>
      -->



     <link name="eyes">
      <inertial>
      <mass value="0.001"/>
      <origin xyz="0 0 0"/>
      <inertia ixx="0.0001" ixy="0.0" ixz="0.0" iyy="0.0001" iyz="0.0" izz="0.0001"/>
    </inertial>
  </link>
  <joint name="eye_joint" type="fixed">
   <origin rpy="0 0 0" xyz="0 0.025 0"/>
    <parent link="camera_link"/>
    <child link="eyes"/>
  </joint>

</robot>

